<?xml version="1.0" ?>
<sdf version="1.4">
  <world name="outdoor">
    <!-- Place user camera -->
    <gui>
      <camera name="user_camera">
        <pose>-11.660200 -5.942800 6.053900 0.000000 0.443643 0.352194</pose>
      </camera>
    </gui>
    <scene>
      <ambient>0.2 0.2 0.2 1.0</ambient>
      <grid>false</grid>
      <sky>
        <clouds>
          <speed>4</speed>
        </clouds>
      </sky>
    </scene>

    <!-- Only one ROS interface plugin is required per world, as any other plugin can connect a Gazebo
         topic to a ROS topic (or vise versa). -->
    <!-- <plugin name="ros_interface_plugin" filename="librotors_gazebo_ros_interface_plugin.so"/>-->

    <physics type='ode'>
      <ode>
        <solver>
          <type>quick</type>
          <iters>1000</iters>
          <sor>1.3</sor>
        </solver>
        <constraints>
          <cfm>0</cfm>
          <erp>0.2</erp>
          <contact_max_correcting_vel>100</contact_max_correcting_vel>
          <contact_surface_layer>0.001</contact_surface_layer>
        </constraints>
      </ode>
      <max_step_size>0.01</max_step_size>
      <real_time_factor>1</real_time_factor>
      <real_time_update_rate>100</real_time_update_rate>
      <gravity>0 0 -9.8</gravity>
    </physics>
    <!-- Light Source -->
    <light type="directional" name="sun">
      <cast_shadows>false</cast_shadows>
      <pose>0 0 100 0 0 0</pose>
      <diffuse>0.8 0.8 0.8 1</diffuse>
      <specular>0.9 0.9 0.9 1</specular>
      <attenuation>
        <range>1000</range>
        <constant>0.9</constant>
        <linear>0.01</linear>
        <quadratic>0.001</quadratic>
      </attenuation>
      <direction>0.2 0.2 -0.9</direction>
    </light>
    <light type="point" name="light_bulb">
      <cast_shadows>false</cast_shadows>
      <pose>-14 0 5 0 0 0</pose>
      <diffuse>0.3 0.3 0.3 1</diffuse>
      <specular>0.0 0.0 0.0 1</specular>
      <attenuation>
        <range>80</range>
        <constant>0.9</constant>
        <linear>0.01</linear>
        <quadratic>0.001</quadratic>
      </attenuation>
    </light>
    <include>
      <uri>model://vrc_heightmap_1</uri>
    </include>
    <include>
      <uri>model://grass_plane</uri>
    </include>
    <include>
      <uri>model://speed_limit_sign</uri>
      <name>speed_sign_1</name>
      <static>true</static>
      <pose>15 -5 0 0 0 1.5707</pose>
    </include>
    <include>
      <uri>model://speed_limit_sign</uri>
      <name>speed_sign_2</name>
      <static>true</static>
      <pose>70 5 0 0 0 1.5707</pose>
    </include>
    <include>
      <uri>model://speed_limit_sign</uri>
      <name>speed_sign_3</name>
      <static>true</static>
      <pose>121 13 0 0 0 2.356</pose>
    </include>
    <include>
      <uri>model://speed_limit_sign</uri>
      <name>speed_sign_4</name>
      <static>true</static>
      <pose>155 68 0 0 0 3.1415</pose>
    </include>
    <include>
      <uri>model://speed_limit_sign</uri>
      <name>speed_sign_5</name>
      <static>true</static>
      <pose>175 95 0 0 0 1.5707</pose>
    </include>
    <include>
      <uri>model://house_1</uri>
      <name>house_1_a</name>
      <pose>12 9.5 0 0 0 0</pose>
    </include>
    <include>
      <uri>model://house_1</uri>
      <name>house_1_b</name>
      <pose>129.5 46 0 0 0 1.5707</pose>
    </include>
    <include>
      <uri>model://mailbox</uri>
      <name>mailbox_0</name>
      <static>true</static>
      <pose>18 4 0 0 0 0</pose>
    </include>
    <include>
      <uri>model://mailbox</uri>
      <name>mailbox_1</name>
      <static>true</static>
      <pose>24.5 -4.45 0 0 0 0</pose>
    </include>
    <include>
      <uri>model://gas_station</uri>
      <name>gas_station</name>
      <pose>77 15 0 0 0 -1.5707963267948966</pose>
    </include>
    <include>
      <uri>model://house_2</uri>
      <name>house_2_a</name>
      <pose>30 -8 0 0 0 0</pose>
    </include>
    <include>
      <uri>model://house_2</uri>
      <name>house_2_b</name>
      <pose>158 91 0 0 0 0</pose>
    </include>
    <include>
      <uri>model://house_3</uri>
      <name>house_3_a</name>
      <pose>44 7 0 0 0 0</pose>
    </include>
    <include>
      <uri>model://house_3</uri>
      <name>house_3_b</name>
      <pose>111 26 0 0 0 .78539</pose>
    </include>
    <include>
      <uri>model://house_3</uri>
      <name>house_3_c</name>
      <pose>170 106 0 0 0 0</pose>
    </include>
    <include>
      <uri>model://mailbox</uri>
      <name>mailbox_2</name>
      <static>true</static>
      <pose>59 4.45 0 0 0 0</pose>
    </include>
    <include>
      <uri>model://house_3</uri>
      <name>house_3_d</name>
      <pose>95 7.0 0 0 0 0</pose>
    </include>
    <include>
      <uri>model://dumpster</uri>
      <static>true</static>
      <pose>143 51.5 0 0 0 0</pose>
    </include>
    <include>
      <uri>model://house_2</uri>
      <name>house_2_c</name>
      <pose>135 84.8 0 0 0 0</pose>
    </include>
    <include>
      <uri>model://lamp_post</uri>
      <name>lamp_post_1</name>
      <static>true</static>
      <pose>24 4 0 0 0 0</pose>
    </include>
    <include>
      <uri>model://lamp_post</uri>
      <name>lamp_post_2</name>
      <static>true</static>
      <pose>54 4 0 0 0 0</pose>
    </include>
    <include>
      <uri>model://lamp_post</uri>
      <name>lamp_post_3</name>
      <static>true</static>
      <pose>84 4 0 0 0 0</pose>
    </include>
    <include>
      <uri>model://lamp_post</uri>
      <name>lamp_post_4</name>
      <static>true</static>
      <pose>14 -4 0 0 0 3.1415</pose>
    </include>
    <include>
      <uri>model://lamp_post</uri>
      <name>lamp_post_5</name>
      <static>true</static>
      <pose>44 -4 0 0 0 3.1415</pose>
    </include>
    <include>
      <uri>model://lamp_post</uri>
      <name>lamp_post_6</name>
      <static>true</static>
      <pose>74 -4 0 0 0 3.1415</pose>
    </include>
    <include>
      <uri>model://lamp_post</uri>
      <name>lamp_post_7</name>
      <static>true</static>
      <pose>148 104 0 0 0 0</pose>
    </include>
    <include>
      <uri>model://lamp_post</uri>
      <name>lamp_post_8</name>
      <static>true</static>
      <pose>178 104 0 0 0 0</pose>
    </include>
    <include>
      <uri>model://lamp_post</uri>
      <name>lamp_post_9</name>
      <static>true</static>
      <pose>158 96 0 0 0 3.1415</pose>
    </include>
    <include>
      <uri>model://lamp_post</uri>
      <name>lamp_post_10</name>
      <static>true</static>
      <pose>188 96 0 0 0 3.1415</pose>
    </include>
    <include>
      <uri>model://lamp_post</uri>
      <name>lamp_post_11</name>
      <static>true</static>
      <pose>102 8 0 0 0 .785</pose>
    </include>
    <include>
      <uri>model://lamp_post</uri>
      <name>lamp_post_12</name>
      <static>true</static>
      <pose>123 29 0 0 0 .785</pose>
    </include>
    <include>
      <uri>model://lamp_post</uri>
      <name>lamp_post_13</name>
      <static>true</static>
      <pose>144 50 0 0 0 .785</pose>
    </include>
    <include>
      <uri>model://lamp_post</uri>
      <name>lamp_post_14</name>
      <static>true</static>
      <pose>99 -4 0 0 0 3.1415</pose>
    </include>
    <include>
      <uri>model://lamp_post</uri>
      <name>lamp_post_15</name>
      <static>true</static>
      <pose>120 14.5 0 0 0 -2.35</pose>
    </include>
    <include>
      <uri>model://lamp_post</uri>
      <name>lamp_post_16</name>
      <static>true</static>
      <pose>141 35.5 0 0 0 -2.35</pose>
    </include>
    <road name="main_street">
      <width>7.34</width>
      <point>0 0 0.01</point>
      <point>100 0 0.01</point>
      <point>150 50 0.01</point>
      <point>150 100 0.01</point>
      <point>200 100 0.01</point>
    </road>
    <road name="gas_station_street">
      <width>17</width>
      <point>65 25 0.01</point>
      <point>65 3.66 0.01</point>
    </road>
    <model name="road_boxes">
      <static>true</static>
      <link name="link">
        <collision name="collision_1">
          <pose>51 0 0 0 0 0</pose>
          <geometry>
            <box>
              <size>102 7.34 0.02</size>
            </box>
          </geometry>
          <surface>
            <friction>
              <ode>
                <mu>0.8</mu>
                <mu2>0.8</mu2>
              </ode>
            </friction>
          </surface>
        </collision>
        <collision name="collision_2">
          <pose>125 25 0 0 0 0.78539</pose>
          <geometry>
            <box>
              <size>72 7.34 0.02</size>
            </box>
          </geometry>
          <surface>
            <friction>
              <ode>
                <mu>0.8</mu>
                <mu2>0.8</mu2>
              </ode>
            </friction>
          </surface>
        </collision>
        <collision name="collision_3">
          <pose>150 75 0 0 0 0</pose>
          <geometry>
            <box>
              <size>7.34 53 0.02</size>
            </box>
          </geometry>
          <surface>
            <friction>
              <ode>
                <mu>0.8</mu>
                <mu2>0.8</mu2>
              </ode>
            </friction>
          </surface>
        </collision>
        <collision name="collision_4">
          <pose>173.5 100 0 0 0 0</pose>
          <geometry>
            <box>
              <size>54.5 7.34 0.02</size>
            </box>
          </geometry>
          <surface>
            <friction>
              <ode>
                <mu>0.8</mu>
                <mu2>0.8</mu2>
              </ode>
            </friction>
          </surface>
        </collision>
        <collision name="collision_5">
          <pose>198 106 0 0 0 0</pose>
          <geometry>
            <box>
              <size>6 5 0.02</size>
            </box>
          </geometry>
          <surface>
            <friction>
              <ode>
                <mu>0.8</mu>
                <mu2>0.8</mu2>
              </ode>
            </friction>
          </surface>
        </collision>
      </link>
    </model>
    <model name='quad'>
      <link name='base'>
        <inertial>
          <mass>1</mass>
          <inertia>
            <ixx>0.015</ixx>
            <ixy>0</ixy>
            <ixz>0</ixz>
            <iyy>0.015</iyy>
            <iyz>0</iyz>
            <izz>0.007</izz>
          </inertia>
          <pose>0 0 0.1 0 -0 0</pose>
        </inertial>
        <collision name='base'>
          <geometry>
            <cylinder>
              <radius>0.1</radius>
              <length>0.05</length>
            </cylinder>
          </geometry>
          <max_contacts>10</max_contacts>
          <surface>
            <contact>
              <ode/>
            </contact>
            <bounce/>
            <friction>
              <torsional>
                <ode/>
              </torsional>
              <ode/>
            </friction>
          </surface>
        </collision>
        <collision name='land_1'>
          <pose>0.1 0 0 0 -0 0</pose>
          <geometry>
            <sphere>
              <radius>0.03</radius>
            </sphere>
          </geometry>
          <max_contacts>10</max_contacts>
          <surface>
            <contact>
              <ode/>
            </contact>
            <bounce/>
            <friction>
              <torsional>
                <ode/>
              </torsional>
              <ode/>
            </friction>
          </surface>
        </collision>
        <collision name='land_2'>
          <pose>-0.05 0.086 0 0 -0 0</pose>
          <geometry>
            <sphere>
              <radius>0.03</radius>
            </sphere>
          </geometry>
          <max_contacts>10</max_contacts>
          <surface>
            <contact>
              <ode/>
            </contact>
            <bounce/>
            <friction>
              <torsional>
                <ode/>
              </torsional>
              <ode/>
            </friction>
          </surface>
        </collision>
        <collision name='land_3'>
          <pose>-0.05 -0.086 0 0 -0 0</pose>
          <geometry>
            <sphere>
              <radius>0.03</radius>
            </sphere>
          </geometry>
          <max_contacts>10</max_contacts>
          <surface>
            <contact>
              <ode/>
            </contact>
            <bounce/>
            <friction>
              <torsional>
                <ode/>
              </torsional>
              <ode/>
            </friction>
          </surface>
        </collision>
        <visual name='body'>
          <geometry>
            <cylinder>
              <radius>0.08</radius>
              <length>0.05</length>
            </cylinder>
          </geometry>
          <material>
            <ambient>1 0.6 0.4 1</ambient>
            <diffuse>1 1 1 1</diffuse>
          </material>
        </visual>
        <visual name='arm-1'>
          <pose>0.125 0 0 3.14159 1.57079 3.14159</pose>
          <geometry>
            <cylinder>
              <radius>0.01</radius>
              <length>0.25</length>
            </cylinder>
          </geometry>
          <material>
            <ambient>1 0.4 0.4 1</ambient>
            <diffuse>1 1 1 1</diffuse>
          </material>
        </visual>
        <visual name='arm-2'>
          <pose>0 0.125 0 3.14159 1.57079 -1.57079</pose>
          <geometry>
            <cylinder>
              <radius>0.01</radius>
              <length>0.25</length>
            </cylinder>
          </geometry>
          <material>
            <ambient>0.6 0.6 0.6 1</ambient>
            <diffuse>1 1 1 1</diffuse>
          </material>
        </visual>
        <visual name='arm-3'>
          <pose>-0.125 0 0 3.14159 1.57079 3.14159</pose>
          <geometry>
            <cylinder>
              <radius>0.01</radius>
              <length>0.25</length>
            </cylinder>
          </geometry>
          <material>
            <ambient>0.6 0.6 0.6 1</ambient>
            <diffuse>1 1 1 1</diffuse>
          </material>
        </visual>
        <visual name='arm-4'>
          <pose>0 -0.125 0 3.14159 1.57079 -1.57079</pose>
          <geometry>
            <cylinder>
              <radius>0.01</radius>
              <length>0.25</length>
            </cylinder>
          </geometry>
          <material>
            <ambient>0.6 0.6 0.6 1</ambient>
            <diffuse>1 1 1 1</diffuse>
          </material>
        </visual>
        <self_collide>0</self_collide>
        <enable_wind>0</enable_wind>
        <kinematic>0</kinematic>
      </link>
      <frame name='rotor-1::__model__' attached_to='rotor-1::propeller'>
        <pose relative_to='__model__'>0.23 0 0 0 -0 0</pose>
      </frame>
      <link name='rotor-1::propeller'>
        <inertial>
          <mass>0.07</mass>
          <inertia>
            <ixx>4e-05</ixx>
            <ixy>0</ixy>
            <ixz>0</ixz>
            <iyy>4e-05</iyy>
            <iyz>0</iyz>
            <izz>8e-05</izz>
          </inertia>
          <pose>0 0 0 0 -0 0</pose>
        </inertial>
        <collision name='collision'>
          <pose>0 0 0.04 0 -0 0</pose>
          <geometry>
            <cylinder>
              <radius>0.127</radius>
              <length>0.002</length>
            </cylinder>
          </geometry>
          <max_contacts>10</max_contacts>
          <surface>
            <contact>
              <ode/>
            </contact>
            <bounce/>
            <friction>
              <torsional>
                <ode/>
              </torsional>
              <ode/>
            </friction>
          </surface>
        </collision>
        <visual name='motor'>
          <pose>0 0 0.015 0 -0 0</pose>
          <geometry>
            <cylinder>
              <radius>0.015</radius>
              <length>0.03</length>
            </cylinder>
          </geometry>
          <material>
            <ambient>0.1 0.1 0.1 1</ambient>
            <diffuse>1 1 1 1</diffuse>
          </material>
        </visual>
        <visual name='axle'>
          <pose>0 0 0.035 0 -0 0</pose>
          <geometry>
            <cylinder>
              <radius>0.002</radius>
              <length>0.01</length>
            </cylinder>
          </geometry>
          <material>
            <ambient>0.1 0.1 0.1 1</ambient>
            <diffuse>1 1 1 1</diffuse>
          </material>
        </visual>
        <visual name='blade'>
          <pose>0 0 0.04 0 -0 0</pose>
          <geometry>
            <box>
              <size>0.25 0.03 0.002</size>
            </box>
          </geometry>
          <material>
            <ambient>0.1 0.1 0.1 1</ambient>
            <diffuse>1 1 1 1</diffuse>
          </material>
        </visual>
        <pose relative_to='rotor-1::__model__'>0 0 0 0 -0 0</pose>
        <self_collide>0</self_collide>
        <enable_wind>0</enable_wind>
        <kinematic>0</kinematic>
      </link>
      <joint name='rotor-1' type='revolute'>
        <parent>base</parent>
        <child>rotor-1::propeller</child>
        <axis>
          <xyz>0 0 1</xyz>
          <limit>
            <lower>-1e+16</lower>
            <upper>1e+16</upper>
          </limit>
          <dynamics>
            <spring_reference>0</spring_reference>
            <spring_stiffness>0</spring_stiffness>
          </dynamics>
        </axis>
      </joint>
      <frame name='rotor-2::__model__' attached_to='rotor-2::propeller'>
        <pose relative_to='__model__'>0 0.23 0 0 -0 0</pose>
      </frame>
      <link name='rotor-2::propeller'>
        <inertial>
          <mass>0.07</mass>
          <inertia>
            <ixx>4e-05</ixx>
            <ixy>0</ixy>
            <ixz>0</ixz>
            <iyy>4e-05</iyy>
            <iyz>0</iyz>
            <izz>8e-05</izz>
          </inertia>
          <pose>0 0 0 0 -0 0</pose>
        </inertial>
        <collision name='collision'>
          <pose>0 0 0.04 0 -0 0</pose>
          <geometry>
            <cylinder>
              <radius>0.127</radius>
              <length>0.002</length>
            </cylinder>
          </geometry>
          <max_contacts>10</max_contacts>
          <surface>
            <contact>
              <ode/>
            </contact>
            <bounce/>
            <friction>
              <torsional>
                <ode/>
              </torsional>
              <ode/>
            </friction>
          </surface>
        </collision>
        <visual name='motor'>
          <pose>0 0 0.015 0 -0 0</pose>
          <geometry>
            <cylinder>
              <radius>0.015</radius>
              <length>0.03</length>
            </cylinder>
          </geometry>
          <material>
            <ambient>0.1 0.1 0.1 1</ambient>
            <diffuse>1 1 1 1</diffuse>
          </material>
        </visual>
        <visual name='axle'>
          <pose>0 0 0.035 0 -0 0</pose>
          <geometry>
            <cylinder>
              <radius>0.002</radius>
              <length>0.01</length>
            </cylinder>
          </geometry>
          <material>
            <ambient>0.1 0.1 0.1 1</ambient>
            <diffuse>1 1 1 1</diffuse>
          </material>
        </visual>
        <visual name='blade'>
          <pose>0 0 0.04 0 -0 0</pose>
          <geometry>
            <box>
              <size>0.25 0.03 0.002</size>
            </box>
          </geometry>
          <material>
            <ambient>0.1 0.1 0.1 1</ambient>
            <diffuse>1 1 1 1</diffuse>
          </material>
        </visual>
        <pose relative_to='rotor-2::__model__'>0 0 0 0 -0 0</pose>
        <self_collide>0</self_collide>
        <enable_wind>0</enable_wind>
        <kinematic>0</kinematic>
      </link>
      <joint name='rotor-2' type='revolute'>
        <parent>base</parent>
        <child>rotor-2::propeller</child>
        <axis>
          <xyz>0 0 1</xyz>
          <limit>
            <lower>-1e+16</lower>
            <upper>1e+16</upper>
          </limit>
          <dynamics>
            <spring_reference>0</spring_reference>
            <spring_stiffness>0</spring_stiffness>
          </dynamics>
        </axis>
      </joint>
      <frame name='rotor-3::__model__' attached_to='rotor-3::propeller'>
        <pose relative_to='__model__'>-0.23 0 0 0 -0 0</pose>
      </frame>
      <link name='rotor-3::propeller'>
        <inertial>
          <mass>0.07</mass>
          <inertia>
            <ixx>4e-05</ixx>
            <ixy>0</ixy>
            <ixz>0</ixz>
            <iyy>4e-05</iyy>
            <iyz>0</iyz>
            <izz>8e-05</izz>
          </inertia>
          <pose>0 0 0 0 -0 0</pose>
        </inertial>
        <collision name='collision'>
          <pose>0 0 0.04 0 -0 0</pose>
          <geometry>
            <cylinder>
              <radius>0.127</radius>
              <length>0.002</length>
            </cylinder>
          </geometry>
          <max_contacts>10</max_contacts>
          <surface>
            <contact>
              <ode/>
            </contact>
            <bounce/>
            <friction>
              <torsional>
                <ode/>
              </torsional>
              <ode/>
            </friction>
          </surface>
        </collision>
        <visual name='motor'>
          <pose>0 0 0.015 0 -0 0</pose>
          <geometry>
            <cylinder>
              <radius>0.015</radius>
              <length>0.03</length>
            </cylinder>
          </geometry>
          <material>
            <ambient>0.1 0.1 0.1 1</ambient>
            <diffuse>1 1 1 1</diffuse>
          </material>
        </visual>
        <visual name='axle'>
          <pose>0 0 0.035 0 -0 0</pose>
          <geometry>
            <cylinder>
              <radius>0.002</radius>
              <length>0.01</length>
            </cylinder>
          </geometry>
          <material>
            <ambient>0.1 0.1 0.1 1</ambient>
            <diffuse>1 1 1 1</diffuse>
          </material>
        </visual>
        <visual name='blade'>
          <pose>0 0 0.04 0 -0 0</pose>
          <geometry>
            <box>
              <size>0.25 0.03 0.002</size>
            </box>
          </geometry>
          <material>
            <ambient>0.1 0.1 0.1 1</ambient>
            <diffuse>1 1 1 1</diffuse>
          </material>
        </visual>
        <pose relative_to='rotor-3::__model__'>0 0 0 0 -0 0</pose>
        <self_collide>0</self_collide>
        <enable_wind>0</enable_wind>
        <kinematic>0</kinematic>
      </link>
      <joint name='rotor-3' type='revolute'>
        <parent>base</parent>
        <child>rotor-3::propeller</child>
        <axis>
          <xyz>0 0 1</xyz>
          <limit>
            <lower>-1e+16</lower>
            <upper>1e+16</upper>
          </limit>
          <dynamics>
            <spring_reference>0</spring_reference>
            <spring_stiffness>0</spring_stiffness>
          </dynamics>
        </axis>
      </joint>
      <frame name='rotor-4::__model__' attached_to='rotor-4::propeller'>
        <pose relative_to='__model__'>0 -0.23 0 0 -0 0</pose>
      </frame>
      <link name='rotor-4::propeller'>
        <inertial>
          <mass>0.07</mass>
          <inertia>
            <ixx>4e-05</ixx>
            <ixy>0</ixy>
            <ixz>0</ixz>
            <iyy>4e-05</iyy>
            <iyz>0</iyz>
            <izz>8e-05</izz>
          </inertia>
          <pose>0 0 0 0 -0 0</pose>
        </inertial>
        <collision name='collision'>
          <pose>0 0 0.04 0 -0 0</pose>
          <geometry>
            <cylinder>
              <radius>0.127</radius>
              <length>0.002</length>
            </cylinder>
          </geometry>
          <max_contacts>10</max_contacts>
          <surface>
            <contact>
              <ode/>
            </contact>
            <bounce/>
            <friction>
              <torsional>
                <ode/>
              </torsional>
              <ode/>
            </friction>
          </surface>
        </collision>
        <visual name='motor'>
          <pose>0 0 0.015 0 -0 0</pose>
          <geometry>
            <cylinder>
              <radius>0.015</radius>
              <length>0.03</length>
            </cylinder>
          </geometry>
          <material>
            <ambient>0.1 0.1 0.1 1</ambient>
            <diffuse>1 1 1 1</diffuse>
          </material>
        </visual>
        <visual name='axle'>
          <pose>0 0 0.035 0 -0 0</pose>
          <geometry>
            <cylinder>
              <radius>0.002</radius>
              <length>0.01</length>
            </cylinder>
          </geometry>
          <material>
            <ambient>0.1 0.1 0.1 1</ambient>
            <diffuse>1 1 1 1</diffuse>
          </material>
        </visual>
        <visual name='blade'>
          <pose>0 0 0.04 0 -0 0</pose>
          <geometry>
            <box>
              <size>0.25 0.03 0.002</size>
            </box>
          </geometry>
          <material>
            <ambient>0.1 0.1 0.1 1</ambient>
            <diffuse>1 1 1 1</diffuse>
          </material>
        </visual>
        <pose relative_to='rotor-4::__model__'>0 0 0 0 -0 0</pose>
        <self_collide>0</self_collide>
        <enable_wind>0</enable_wind>
        <kinematic>0</kinematic>
      </link>
      <joint name='rotor-4' type='revolute'>
        <parent>base</parent>
        <child>rotor-4::propeller</child>
        <axis>
          <xyz>0 0 1</xyz>
          <limit>
            <lower>-1e+16</lower>
            <upper>1e+16</upper>
          </limit>
          <dynamics>
            <spring_reference>0</spring_reference>
            <spring_stiffness>0</spring_stiffness>
          </dynamics>
        </axis>
      </joint>
      <link name='down_camera_link'>
        <pose>0 0 0 3.14159 1.57079 3.14159</pose>
        <inertial>
          <pose>0 0 0 0 -0 0</pose>
          <mass>0.001</mass>
          <inertia>
            <ixx>3.2061e-05</ixx>
            <ixy>-1.169e-08</ixy>
            <ixz>-4.2601e-10</ixz>
            <iyy>3.0815e-05</iyy>
            <iyz>5.2182e-10</iyz>
            <izz>5.1652e-06</izz>
          </inertia>
        </inertial>
        <visual name='down_camera_visual'>
          <pose>0 0 0 0 -0 0</pose>
          <geometry>
            <cylinder>
              <radius>0.02</radius>
              <length>0.04</length>
            </cylinder>
          </geometry>
          <material>
            <ambient>0.1 0.1 0.1 1</ambient>
            <diffuse>1 1 1 1</diffuse>
          </material>
        </visual>
        <gravity>1</gravity>
        <velocity_decay/>
        <self_collide>0</self_collide>
        <sensor name='down_camera' type='camera'>
          <pose>0 0 0 0 -0 0</pose>
          <camera>
            <horizontal_fov>1.2</horizontal_fov>
            <image>
              <format>R8G8B8</format>
              <width>640</width>
              <height>480</height>
            </image>
            <clip>
              <near>0.05</near>
              <far>15000</far>
            </clip>
          </camera>
          <always_on>1</always_on>
          <update_rate>10</update_rate>
          <plugin name='camera_en_ros' filename='libgazebo_ros_camera.so'>
            <robotNamespace/>
            <cameraName>down_camera_link</cameraName>
            <imageTopicName>down_raw_image</imageTopicName>
            <cameraInfoTopicName>down_info_image</cameraInfoTopicName>
            <FrameName>downCameraImage</FrameName>
            <Cy>0</Cy>
            <Cx>0</Cx>
            <updateRate>30.0</updateRate>
          </plugin>
        </sensor>
        <enable_wind>0</enable_wind>
        <kinematic>0</kinematic>
      </link>
      <joint name='down_camera_joint' type='fixed'>
        <child>down_camera_link</child>
        <parent>base</parent>
        <pose>0 0 0 0 -0 0</pose>
        <axis>
          <xyz>1 0 0</xyz>
          <limit>
            <lower>-1e+16</lower>
            <upper>1e+16</upper>
          </limit>
        </axis>
      </joint>
      <plugin name='mrsim' filename='mrsim-gazebo.so'>
        <link>base</link>
        <rotors>
          <noise>0.03</noise>
          <cf>6.5e-4</cf>
          <ct>1e-5</ct>
          <rotor>
            <joint spin='cw'>rotor-1</joint>
          </rotor>
          <rotor>
            <joint spin='ccw'>rotor-2</joint>
          </rotor>
          <rotor>
            <joint spin='cw'>rotor-3</joint>
          </rotor>
          <rotor>
            <joint spin='ccw'>rotor-4</joint>
          </rotor>
        </rotors>
      </plugin>
      <pose>0 0 0.02 0 -0 0</pose>
    </model>
    <plugin name='optitrack' filename='optitrack-gazebo.so'>
      <hz>1000</hz>
      <port>1509</port>
      <publish>
        <link>quad::base</link>
        <name>QR</name>
      </publish>
    </plugin>
  </world>
</sdf>
