<?xml version="1.0" ?>
<sdf version="1.5">
  <model name="mrsim-quadrotor-cam">
    <link name="base">
      <inertial>
        <mass>1.0</mass>
        <inertia>
          <ixx>0.015</ixx><ixy>0</ixy><ixz>0</ixz>
          <iyy>0.015</iyy><iyz>0</iyz>
          <izz>0.007</izz>
        </inertia>
      </inertial>

      <collision name="base">
        <geometry>
          <cylinder><radius>0.1</radius><length>0.05</length></cylinder>
        </geometry>
      </collision>
      <!-- three spheres to make contact stable -->
      <collision name="land_1">
        <pose>0.1 0 0 0 0 0</pose>
        <geometry>
          <sphere><radius>0.03</radius></sphere>
        </geometry>
      </collision>
      <collision name="land_2">
        <pose>-0.05 0.086 0 0 0 0</pose>
        <geometry>
          <sphere><radius>0.03</radius></sphere>
        </geometry>
      </collision>
      <collision name="land_3">
        <pose>-0.05 -0.086 0 0 0 0</pose>
        <geometry>
          <sphere><radius>0.03</radius></sphere>
        </geometry>
      </collision>

      <visual name="body">
        <geometry>
          <cylinder><radius>0.08</radius><length>0.05</length></cylinder>
        </geometry>
        <material>
          <ambient>1.0 0.6 0.4 1</ambient>
          <diffuse>1.0 1.0 1.0 1</diffuse>
        </material>
      </visual>

      <visual name="arm-1">
        <pose>0.125 0 0 0 1.5708 0</pose>
        <geometry>
          <cylinder><radius>0.01</radius><length>0.25</length></cylinder>
        </geometry>
        <material>
          <ambient>1.0 0.4 0.4 1</ambient>
          <diffuse>1.0 1.0 1.0 1</diffuse>
        </material>
      </visual>
      <visual name="arm-2">
        <pose>0 0.125 0 0 1.5708 1.5708</pose>
        <geometry>
          <cylinder><radius>0.01</radius><length>0.25</length></cylinder>
        </geometry>
        <material>
          <ambient>0.6 0.6 0.6 1</ambient>
          <diffuse>1.0 1.0 1.0 1</diffuse>
        </material>
      </visual>
      <visual name="arm-3">
        <pose>-0.125 0 0 0 1.5708 0</pose>
        <geometry>
          <cylinder><radius>0.01</radius><length>0.25</length></cylinder>
        </geometry>
        <material>
          <ambient>0.6 0.6 0.6 1</ambient>
          <diffuse>1.0 1.0 1.0 1</diffuse>
        </material>
      </visual>
      <visual name="arm-4">
        <pose>0 -0.125 0 0 1.5708 1.5708</pose>
        <geometry>
          <cylinder><radius>0.01</radius><length>0.25</length></cylinder>
        </geometry>
        <material>
          <ambient>0.6 0.6 0.6 1</ambient>
          <diffuse>1.0 1.0 1.0 1</diffuse>
        </material>
      </visual>
    </link>

    <include>
      <uri>model://mrsim-rotor</uri>
      <name>rotor-1</name>
      <pose>0.23 0 0 0 0 0</pose>
    </include>
    <joint name="rotor-1" type="revolute">
      <parent>base</parent>
      <child>rotor-1::propeller</child>
      <axis><xyz>0 0 1</xyz></axis>
    </joint>

    <include>
      <uri>model://mrsim-rotor</uri>
      <name>rotor-2</name>
      <pose>0 0.23 0 0 0 0</pose>
    </include>
    <joint name="rotor-2" type="revolute">
      <parent>base</parent>
      <child>rotor-2::propeller</child>
      <axis><xyz>0 0 1</xyz></axis>
    </joint>
    
    <include>
      <uri>model://mrsim-rotor</uri>
      <name>rotor-3</name>
      <pose>-0.23 0 0 0 0 0</pose>
    </include>
    <joint name="rotor-3" type="revolute">
      <parent>base</parent>
      <child>rotor-3::propeller</child>
      <axis><xyz>0 0 1</xyz></axis>
    </joint>

    <include>
      <uri>model://mrsim-rotor</uri>
      <name>rotor-4</name>
      <pose>0 -0.23 0 0 0 0</pose>
    </include>
    <joint name="rotor-4" type="revolute">
      <parent>base</parent>
      <child>rotor-4::propeller</child>
      <axis><xyz>0 0 1</xyz></axis>
    </joint>

    <!--down cam link-->
    <link name="down_camera_link">
      <pose>0 0 0 0 1.5708 0 </pose>
      <inertial>
        <pose>0 0 0 0 0 0</pose>
        <mass>0.001</mass>
        <inertia>
          <ixx>3.2061e-05</ixx>
          <ixy>-1.169e-08</ixy>
          <ixz>-4.2601e-10</ixz>
          <iyy>3.0815e-05</iyy>
          <iyz>5.2182e-10</iyz>
          <izz>5.1652e-06</izz>
        </inertia>
      </inertial>
      <visual name='down_camera_visual'>
        <pose>0 0 0 0 0 0 </pose>
        <geometry>
          <cylinder><radius>0.02</radius><length>0.04</length></cylinder>
        </geometry>
        <material>
          <ambient>0.1 0.1 0.1 1</ambient>
          <diffuse>1.0 1.0 1.0 1</diffuse>
        </material>
      </visual>
      <gravity>1</gravity>
      <velocity_decay/>
      <self_collide>0</self_collide>
      <sensor name="down_camera" type="camera">                 <!-- name of sensor topic as well -->
        <pose>0 0 0 0 0 0</pose>
        <camera>
          <horizontal_fov>1</horizontal_fov>
          <image>
            <format>R8G8B8</format>
            <width>640</width>
            <height>480</height>
          </image>
          <clip>
            <near>0.05</near>
            <far>15000</far>
          </clip>
        </camera>
        <always_on>1</always_on>
        <update_rate>10</update_rate>
        <!-- <visualize>true</visualize> -->
        <plugin filename="libgazebo_ros_camera.so" name="camera_en_ros">
          <robotNamespace>quad1</robotNamespace>
          <cameraName>down_camera_link</cameraName>
          <imageTopicName>down_raw_image</imageTopicName>
          <cameraInfoTopicName>down_info_image</cameraInfoTopicName>
          <FrameName>downCameraImage</FrameName>
          <Cy>0</Cy>
          <Cx>0</Cx>
          <updateRate>30.0</updateRate>
        </plugin>
      </sensor>
    </link>
    <joint name='down_camera_joint' type='fixed'>
      <child>down_camera_link</child>
      <parent>base</parent>
      <pose>0 0 0 0 0 0</pose>
      <axis>
        <xyz>1 0 0</xyz> 	<!--Useless... no? -->
      </axis>
    </joint>
    <!--down cam link end-->
    
    <plugin name="mrsim" filename="mrsim-gazebo.so">
      <link>base</link>

      <rotors>
        <noise>0.03</noise>
        <cf>6.5e-4</cf>
        <ct>1e-5</ct>
        <rotor><joint spin="cw">rotor-1</joint></rotor>
        <rotor><joint spin="ccw">rotor-2</joint></rotor>
        <rotor><joint spin="cw">rotor-3</joint></rotor>
        <rotor><joint spin="ccw">rotor-4</joint></rotor>
      </rotors>
    </plugin>
  </model>
</sdf>
